Workbook

Sheet Sheet1
A1: Nota | B1: ASDAS | C1: Início avaria | D1: Data de criação | E1: Fim planejado | F1: Data conclusão | G1: Conclusão desejada | H1: Texto de grupo de codes para medida | I1: Grupo de codes | J1: Status do sistema | K1: GrpCódigos | L1: Tipo de nota | M1: Code codificação | N1: Descrição | O1: Encerram.por data | P1: Texto code para codificação | Q1: Texto de code medida | R1: Cidade
A2: 1019981071 | B2: =VLOOKUP(A2,Planilha1!A:A,1,0) -> #N/A | C2: 46142 | D2: 46142 | E2: 46175 | G2: 46190 | H2: Inspeção de Serviço Técnico | I2: SERTECRE | J2: MEDA | K2: INSSETEC | L2: ST | M2: DSRD | N2: Serviço Técnico | P2: Deslocamento de Rede | Q2: Em Execução | R2: MACEIO
A3: 1019982478 | B3: =VLOOKUP(A3,Planilha1!A:A,1,0) -> #N/A | C3: 46142 | D3: 46142 | E3: 46175 | G3: 46190 | H3: Inspeção de Serviço Técnico | I3: SERTECRE | J3: MEDA | K3: INSSETEC | L3: ST | M3: DSRD | N3: Serviço Técnico | P3: Deslocamento de Rede | Q3: Em Execução | R3: SAO LUIS DO QUITUNDE
A4: 1019985312 | B4: =VLOOKUP(A4,Planilha1!A:A,1,0) -> #N/A | C4: 46142 | D4: 46142 | E4: 46175 | G4: 46190 | H4: Inspeção de Serviço Técnico | I4: SERTECRE | J4: MEDA | K4: INSSETEC | L4: ST | M4: DSPT | N4: Serviço Técnico | P4: Deslocamento de Poste | Q4: Em Execução | R4: TEOTONIO VILELA
A5: 1019987372 | B5: =VLOOKUP(A5,Planilha1!A:A,1,0) -> #N/A | C5: 46142 | D5: 46142 | E5: 46175 | G5: 46190 | H5: Inspeção de Serviço Técnico | I5: SERTECRE | J5: MEDA | K5: INSSETEC | L5: ST | M5: DSPT | N5: Serviço Técnico | P5: Deslocamento de Poste | Q5: Em Execução | R5: ARAPIRACA
A6: 1020010277 | B6: =VLOOKUP(A6,Planilha1!A:A,1,0) -> #N/A | C6: 46146 | D6: 46146 | E6: 46176 | G6: 46191 | H6: Inspeção de Serviço Técnico | I6: SERTECRE | J6: MEDA | K6: INSSETEC | L6: ST | M6: DSPT | N6: Serviço Técnico | P6: Deslocamento de Poste | Q6: Em Execução | R6: VICOSA
A7: 1020010871 | B7: =VLOOKUP(A7,Planilha1!A:A,1,0) -> #N/A | C7: 46146 | D7: 46146 | E7: 46176 | G7: 46191 | H7: Inspeção de Serviço Técnico | I7: SERTECRE | J7: MEDA | K7: INSSETEC | L7: ST | M7: SBCM | N7: Serviço Técnico | P7: Substituição por Cabo Multiplexado | Q7: Em Execução | R7: DELMIRO GOUVEIA
A8: 1020015057 | B8: =VLOOKUP(A8,Planilha1!A:A,1,0) -> #N/A | C8: 46146 | D8: 46146 | E8: 46176 | G8: 46191 | H8: Inspeção de Serviço Técnico | I8: SERTECRE | J8: MEDA | K8: INSSETEC | L8: ST | M8: DSRD | N8: Serviço Técnico | P8: Deslocamento de Rede | Q8: Em Execução | R8: MARAGOGI
A9: 1020015213 | B9: =VLOOKUP(A9,Planilha1!A:A,1,0) -> #N/A | C9: 46146 | D9: 46146 | E9: 46176 | G9: 46191 | H9: Inspeção de Serviço Técnico | I9: SERTECRE | J9: MEDA | K9: INSSETEC | L9: ST | M9: AFRD | N9: Serviço Técnico | P9: Afastamento de Rede | Q9: Em Execução | R9: CAMPO ALEGRE
A10: 1020017905 | B10: =VLOOKUP(A10,Planilha1!A:A,1,0) -> #N/A | C10: 46146 | D10: 46146 | E10: 46176 | G10: 46191 | H10: Inspeção de Serviço Técnico | I10: SERTECRE | J10: MEDA | K10: INSSETEC | L10: ST | M10: DSRD | N10: Serviço Técnico | P10: Deslocamento de Rede | Q10: Em Execução | R10: OLHO D AGUA DAS FLORES
A11: 1020026564 | B11: =VLOOKUP(A11,Planilha1!A:A,1,0) -> #N/A | C11: 46147 | D11: 46147 | E11: 46178 | G11: 46192 | H11: Inspeção de Serviço Técnico | I11: SERTECRE | J11: MEDA | K11: INSSETEC | L11: ST | M11: DSPT | N11: Serviço Técnico | P11: Deslocamento de Poste | Q11: Em Execução | R11: MACEIO
A12: 1020026760 | B12: =VLOOKUP(A12,Planilha1!A:A,1,0) -> #N/A | C12: 46147 | D12: 46147 | E12: 46177 | G12: 46192 | H12: Inspeção de Serviço Técnico | I12: SERTECRE | J12: MEDA | K12: INSSETEC | L12: ST | M12: DSRD | N12: Serviço Técnico | P12: Deslocamento de Rede | Q12: Em Execução | R12: MESSIAS
A13: 1020028703 | B13: =VLOOKUP(A13,Planilha1!A:A,1,0) -> #N/A | C13: 46147 | D13: 46147 | E13: 46178 | G13: 46192 | H13: Inspeção de Serviço Técnico | I13: SERTECRE | J13: MEDA | K13: INSSETEC | L13: ST | M13: SBCM | N13: Serviço Técnico | P13: Substituição por Cabo Multiplexado | Q13: Em Execução | R13: MACEIO
... A93: 1020218483 | B93: =VLOOKUP(A93,Planilha1!A:A,1,0) -> #N/A | C93: 46162 | D93: 46162 | E93: 46192 | G93: 46209 | H93: Inspeção de Serviço Técnico | I93: SERTECRE | J93: MEDA | K93: INSSETEC | L93: ST | M93: AFRD | N93: Serviço Técnico | P93: Afastamento de Rede | Q93: Em Execução | R93: MACEIO
A94: 1020218980 | B94: =VLOOKUP(A94,Planilha1!A:A,1,0) -> #N/A | C94: 46162 | D94: 46178 | E94: 46182 | G94: 46192 | H94: Realizar orçamento | I94: VIABILID | J94: MEDA | K94: ORCAMENT | L94: VT | M94: VTAT | N94: Viabilidade Técnica | P94: Viabilidade Técnica AT | Q94: Em execução
A95: 1020219054 | B95: =VLOOKUP(A95,Planilha1!A:A,1,0) -> #N/A | C95: 46162 | D95: 46162 | E95: 46192 | G95: 46209 | H95: Inspeção de Serviço Técnico | I95: SERTECRE | J95: MEDA | K95: INSSETEC | L95: ST | M95: AFRD | N95: Serviço Técnico | P95: Afastamento de Rede | Q95: Em Execução | R95: SANTANA DO IPANEMA
A96: 1020220405 | B96: =VLOOKUP(A96,Planilha1!A:A,1,0) -> #N/A | C96: 46162 | D96: 46162 | E96: 46192 | G96: 46209 | H96: Inspeção de Serviço Técnico | I96: SERTECRE | J96: MEDA | K96: INSSETEC | L96: ST | M96: SBCM | N96: Serviço Técnico | P96: Substituição por Cabo Multiplexado | Q96: Em Execução | R96: SANTANA DO IPANEMA
A97: 1020229169 | B97: =VLOOKUP(A97,Planilha1!A:A,1,0) -> #N/A | C97: 46163 | D97: 46163 | E97: 46195 | G97: 46209 | H97: Inspeção de Serviço Técnico | I97: SERTECRE | J97: MEDA | K97: INSSETEC | L97: ST | M97: AFRD | N97: Serviço Técnico | P97: Afastamento de Rede | Q97: Em Execução | R97: BOCA DA MATA
A98: 1020229749 | B98: =VLOOKUP(A98,Planilha1!A:A,1,0) -> #N/A | C98: 46163 | D98: 46163 | E98: 46195 | G98: 46209 | H98: Inspeção de Serviço Técnico | I98: SERTECRE | J98: MEDA | K98: INSSETEC | L98: ST | M98: DSRD | N98: Serviço Técnico | P98: Deslocamento de Rede | Q98: Em Execução | R98: MARAGOGI
A99: 1020230287 | B99: =VLOOKUP(A99,Planilha1!A:A,1,0) -> #N/A | C99: 46163 | D99: 46178 | E99: 46182 | G99: 46195 | H99: Realizar orçamento | I99: VIABILID | J99: MEDA | K99: ORCAMENT | L99: VT | M99: VTAT | N99: Viabilidade Técnica | P99: Viabilidade Técnica AT | Q99: Em execução
A100: 1020231518 | B100: =VLOOKUP(A100,Planilha1!A:A,1,0) -> #N/A | C100: 46163 | D100: 46174 | E100: 46175 | G100: 46195 | H100: Calculo de ERD | I100: TROCPABT | J100: MEDA | K100: CALCERD | L100: TP | M100: TPCA | N100: Troca de Padrão | P100: Troca de Padrão com Acréscimo de Carga | Q100: Em Execução | R100: MACEIO
A101: 1020233090 | B101: =VLOOKUP(A101,Planilha1!A:A,1,0) -> #N/A | C101: 46163 | D101: 46168 | E101: 46169 | G101: 46195 | H101: Calculo de ERD | I101: TROCPABT | J101: MEDA | K101: CALCERD | L101: TP | M101: TPCA | N101: Troca de Padrão | P101: Troca de Padrão com Acréscimo de Carga | Q101: Em Execução | R101: MACEIO
A102: 1020243002 | B102: =VLOOKUP(A102,Planilha1!A:A,1,0) -> #N/A | C102: 46164 | D102: 46181 | E102: 46185 | G102: 46196 | H102: Realizar orçamento | I102: VIABILID | J102: MEDA | K102: ORCAMENT | L102: VT | M102: VTAT | N102: Viabilidade Técnica | P102: Viabilidade Técnica AT | Q102: Em execução
A103: 1020243160 | B103: =VLOOKUP(A103,Planilha1!A:A,1,0) -> #N/A | C103: 46164 | D103: 46178 | E103: 46182 | G103: 46196 | H103: Realizar orçamento | I103: VIABILID | J103: MEDA | K103: ORCAMENT | L103: VT | M103: VTAT | N103: Viabilidade Técnica | P103: Viabilidade Técnica AT | Q103: Em execução
A104: 1020243930 | B104: =VLOOKUP(A104,Planilha1!A:A,1,0) -> #N/A | C104: 46164 | D104: 46169 | E104: 46176 | G104: 46199 | H104: Elaborar Orçamento | I104: ORCNXBTN | J104: MEDA | K104: ORCACNBT | L104: OC | M104: OCDF | N104: Orçamento de Conexão | P104: Conexão Definitiva | Q104: Em execução | R104: SAO BRAS
A105: 1020244669 | B105: =VLOOKUP(A105,Planilha1!A:A,1,0) -> #N/A | C105: 46164 | D105: 46164 | E105: 46196 | G105: 46211 | H105: Inspeção de Serviço Técnico | I105: SERTECRE | J105: MEDA | K105: INSSETEC | L105: ST | M105: AFRD | N105: Serviço Técnico | P105: Afastamento de Rede | Q105: Em Execução | R105: SAO JOSE DA TAPERA
A106: 1020244697 | B106: =VLOOKUP(A106,Planilha1!A:A,1,0) -> #N/A | C106: 46164 | D106: 46164 | E106: 46198 | G106: 46212 | H106: Inspeção de Serviço Técnico | I106: SERTECRE | J106: MEDA | K106: INSSETEC | L106: ST | M106: ESRD | N106: Serviço Técnico | P106: Espçamento de rede | Q106: Em Execução | R106: MATRIZ DE CAMARAGIBE
A107: 1020245653 | B107: =VLOOKUP(A107,Planilha1!A:A,1,0) -> #N/A | C107: 46164 | D107: 46164 | E107: 46196 | G107: 46211 | H107: Inspeção de Serviço Técnico | I107: SERTECRE | J107: MEDA | K107: INSSETEC | L107: ST | M107: DSPT | N107: Serviço Técnico | P107: Deslocamento de Poste | Q107: Em Execução | R107: BARRA DE SAO MIGUEL
A108: 1020245910 | B108: =VLOOKUP(A108,Planilha1!A:A,1,0) -> #N/A | C108: 46164 | D108: 46164 | E108: 46196 | G108: 46211 | H108: Inspeção de Serviço Técnico | I108: SERTECRE | J108: MEDA | K108: INSSETEC | L108: ST | M108: DSRD | N108: Serviço Técnico | P108: Deslocamento de Rede | Q108: Em Execução | R108: MARECHAL DEODORO
A109: 1020245971 | B109: =VLOOKUP(A109,Planilha1!A:A,1,0) -> #N/A | C109: 46164 | D109: 46164 | E109: 46196 | G109: 46211 | H109: Inspeção de Serviço Técnico | I109: SERTECRE | J109: MEDA | K109: INSSETEC | L109: ST | M109: DSPT | N109: Serviço Técnico | P109: Deslocamento de Poste | Q109: Em Execução | R109: MACEIO
A110: 1020246223 | B110: =VLOOKUP(A110,Planilha1!A:A,1,0) -> #N/A | C110: 46164 | D110: 46164 | E110: 46196 | G110: 46211 | H110: Inspeção de Serviço Técnico | I110: SERTECRE | J110: MEDA | K110: INSSETEC | L110: ST | M110: SBCM | N110: Serviço Técnico | P110: Substituição por Cabo Multiplexado | Q110: Em Execução | R110: SANTANA DO MUNDAU
A111: 1020246241 | B111: =VLOOKUP(A111,Planilha1!A:A,1,0) -> #N/A | C111: 46164 | D111: 46164 | E111: 46196 | G111: 46211 | H111: Inspeção de Serviço Técnico | I111: SERTECRE | J111: MEDA | K111: INSSETEC | L111: ST | M111: DSPT | N111: Serviço Técnico | P111: Deslocamento de Poste | Q111: Em Execução | R111: MARECHAL DEODORO
A112: 1020247187 | B112: =VLOOKUP(A112,Planilha1!A:A,1,0) -> #N/A | C112: 46164 | D112: 46164 | E112: 46196 | G112: 46211 | H112: Inspeção de Serviço Técnico | I112: SERTECRE | J112: MEDA | K112: INSSETEC | L112: ST | M112: DSPT | N112: Serviço Técnico | P112: Deslocamento de Poste | Q112: Em Execução | R112: MACEIO
A113: 1020247424 | B113: =VLOOKUP(A113,Planilha1!A:A,1,0) -> #N/A | C113: 46164 | D113: 46169 | E113: 46176 | G113: 46199 | H113: Elaborar Orçamento | I113: ORCNXBTN | J113: MEDA | K113: ORCACNBT | L113: OC | M113: OCDF | N113: Orçamento de Conexão | P113: Conexão Definitiva | Q113: Em execução | R113: RIO LARGO
A114: 1020247564 | B114: =VLOOKUP(A114,Planilha1!A:A,1,0) -> #N/A | C114: 46164 | D114: 46174 | E114: 46198 | G114: 46198 | H114: Elab. Estudos e Orçamento C/ Participaçã | I114: MUDMEDLC | J114: MEDA | K114: ELESORCP | L114: MM | M114: MMDL | N114: Mudança do medidor | P114: Mudança de Medidor de Local | Q114: Em Execução | R114: MATRIZ DE CAMARAGIBE
A115: 1020259190 | B115: =VLOOKUP(A115,Planilha1!A:A,1,0) -> #N/A | C115: 46165 | D115: 46181 | E115: 46185 | G115: 46196 | H115: Realizar orçamento | I115: VIABILID | J115: MEDA | K115: ORCAMENT | L115: VT | M115: VTAT | N115: Viabilidade Técnica | P115: Viabilidade Técnica AT | Q115: Em execução | R115: MARAGOGI
... A120: 1020269528 | B120: =VLOOKUP(A120,Planilha1!A:A,1,0) -> #N/A | C120: 46167 | D120: 46167 | E120: 46198 | G120: 46212 | H120: Inspeção de Serviço Técnico | I120: SERTECRE | J120: MEDA | K120: INSSETEC | L120: ST | M120: AFRD | N120: Serviço Técnico | P120: Afastamento de Rede | Q120: Em Execução | R120: MACEIO
A121: 1020269774 | B121: =VLOOKUP(A121,Planilha1!A:A,1,0) -> #N/A | C121: 46167 | D121: 46181 | E121: 46185 | G121: 46198 | H121: Realizar orçamento | I121: VIABILID | J121: MEDA | K121: ORCAMENT | L121: VT | M121: VTAT | N121: Viabilidade Técnica | P121: Viabilidade Técnica AT | Q121: Em execução
A122: 1020269969 | B122: =VLOOKUP(A122,Planilha1!A:A,1,0) -> #N/A | C122: 46167 | D122: 46167 | E122: 46198 | G122: 46212 | H122: Inspeção de Serviço Técnico | I122: SERTECRE | J122: MEDA | K122: INSSETEC | L122: ST | M122: DSPT | N122: Serviço Técnico | P122: Deslocamento de Poste | Q122: Em Execução | R122: ATALAIA
A123: 1020270417 | B123: =VLOOKUP(A123,Planilha1!A:A,1,0) -> #N/A | C123: 46167 | D123: 46167 | E123: 46198 | G123: 46212 | H123: Inspeção de Serviço Técnico | I123: SERTECRE | J123: MEDA | K123: INSSETEC | L123: ST | M123: SBCM | N123: Serviço Técnico | P123: Substituição por Cabo Multiplexado | Q123: Em Execução | R123: MARAGOGI
...

Sheet Planilha1
A1: NOTA
A2: 1020325580
A3: 1020327836
A4: 1020361248
A5: 1020374215
A6: 1020374826
A7: 1020375121
A8: 1020387222
A9: 1020389724
A10: 1020391099
A11: 1020392675
A12: 1020394441
A13: 1020329499
... A20: 1020352369
